Workbook

Sheet Read me
A1: HE-Austenite v1.0
A2: Hydrogen embrittlement of austenitic stainless steels in gaseous hydrogen: base metal and welds
A4: Scope: gaseous hydrogen only. Tested in high-pressure hydrogen gas, or thermally precharged in hydrogen gas and then tested.
A5: Electrochemically charged studies are excluded: cathodic fugacity cannot be converted to an equivalent gas pressure without assumptions.
A7: Release 1.0, 23 September 2026. The 'verified' column marks rows that were independently re-extracted and matched against the source.
A8: Derived values (nickel equivalent, relative ratio) are flagged in the 'derived' column and were not reported as such by the source.
A9: Sources whose data appears only in figures are listed in the Extraction log sheet and are not in the Data sheet.
A11: Compiled by Muhammad Faizan, September 2026. Data CC BY 4.0; code MIT.

Sheet Data
A1: record id | B1: source id | C1: source short | D1: alloy | E1: heat | F1: material family | G1: product form | H1: is weld | I1: zone | J1: weld process | K1: filler metal | L1: ferrite number | M1: hydrogen exposure | N1: h2 pressure MPa | O1: hydrogen content wppm | P1: charging time h | Q1: test temperature K | R1: test temperature C | S1: strain rate per s | T1: test type | U1: property name | V1: reference environment | W1: property reference | X1: property h2 | Y1: relative ratio | Z1: embrittlement flag | AA1: ni equivalent | AB1: derived | AC1: verified | AD1: notes | AE1: RA ratio (base metal) | AF1: RA ratio (weld)
A2: IYER89-EL | B2: S7 | C2: Iyer 1989 | D2: 304 | F2: 300-series (304 type) | G2: unknown | H2: no | I2: base metal | M2: gaseous precharge | N2: 0.1 | O2: 350 | P2: 12 | Q2: 300 | R2: 26.9 | T2: tensile | U2: elongation | V2: uncharged | W2: 43 | X2: 13 | Y2: 0.302 | Z2: significant loss | AB2: relative_ratio | AC2: no | AD2: Iyer, Canadian Metallurgical Quarterly 1989. Stable 304; charged by soaking at 1050 C in Ar-3%H2 slightly above atmospheric pressure for 12 h (350 wppm), water quenched, tested at 27 C. Reference = annealed, 5 wppm. Strengths converted from kg/mm2 at 9.807 MPa per kg/mm2. | AE2: =IF(AND($U2="reduction of area",$H2="no"),$Y2,"") | AF2: =IF(AND($U2="reduction of area",$H2="yes"),$Y2,"")
A3: IYER89-TS | B3: S7 | C3: Iyer 1989 | D3: 304 | F3: 300-series (304 type) | G3: unknown | H3: no | I3: base metal | M3: gaseous precharge | N3: 0.1 | O3: 350 | P3: 12 | Q3: 300 | R3: 26.9 | T3: tensile | U3: tensile strength | V3: uncharged | W3: 508 | X3: 472 | Y3: 0.929 | Z3: moderate loss | AB3: relative_ratio | AC3: no | AD3: Iyer, Canadian Metallurgical Quarterly 1989. Stable 304; charged by soaking at 1050 C in Ar-3%H2 slightly above atmospheric pressure for 12 h (350 wppm), water quenched, tested at 27 C. Reference = annealed, 5 wppm. Strengths converted from kg/mm2 at 9.807 MPa per kg/mm2. | AE3: =IF(AND($U3="reduction of area",$H3="no"),$Y3,"") | AF3: =IF(AND($U3="reduction of area",$H3="yes"),$Y3,"")
A4: MATSUOKA17-304-RA | B4: S9 | C4: Matsuoka 2017 | D4: 304 | F4: 300-series (304 type) | G4: unknown | H4: no | I4: base metal | M4: gaseous in-situ | N4: 96.5 | Q4: 295 | R4: 21.9 | T4: SSRT | U4: reduction of area | V4: air | Y4: 0.37 | Z4: significant loss | AB4: h2_pressure_MPa (midpoint of 78-115 MPa range) | AC4: no | AD4: Matsuoka et al., Solid State Phenomena 258 (2017) 259. SSRT per ASTM G142, 6 mm dia, 30 mm gauge, cross-head 0.002 mm/s, hydrogen gas 78-115 MPa (96.5 recorded as the midpoint), reference air at RT. RRA = 0.37 stated in the text; absolute RA values appear only in figures. Remaining RRA vs Nieq data is figure-only. | AE4: =IF(AND($U4="reduction of area",$H4="no"),$Y4,"") | AF4: =IF(AND($U4="reduction of area",$H4="yes"),$Y4,"")
A5: CASKEY-T10-1-EL | B5: S1 | C5: Caskey 1983 | D5: 304L | F5: 300-series (304 type) | G5: unknown | H5: no | I5: base metal | M5: gaseous precharge | N5: 69 | Q5: 295 | R5: 21.9 | T5: tensile | U5: elongation | V5: uncharged | W5: 32 | X5: 35 | Y5: 1.094 | Z5: no measurable loss | AB5: relative_ratio | AC5: no | AD5: Caskey Table 10, HERF; total elongation barely changed while plastic strain to fracture halved Composition from Caskey Table A-1 (nominal). | AE5: =IF(AND($U5="reduction of area",$H5="no"),$Y5,"") | AF5: =IF(AND($U5="reduction of area",$H5="yes"),$Y5,"")
A6: CASKEY-T10-1-PS | B6: S1 | C6: Caskey 1983 | D6: 304L | F6: 300-series (304 type) | G6: unknown | H6: no | I6: base metal | M6: gaseous precharge | N6: 69 | Q6: 295 | R6: 21.9 | T6: tensile | U6: plastic strain to failure | V6: uncharged | W6: 1.83 | X6: 0.87 | Y6: 0.475 | Z6: significant loss | AB6: relative_ratio | AC6: no | AD6: Caskey Table 10, HERF condition; 69 MPa H2 at 480 K for 55 days; reference = unexposed Composition from Caskey Table A-1 (nominal). | AE6: =IF(AND($U6="reduction of area",$H6="no"),$Y6,"") | AF6: =IF(AND($U6="reduction of area",$H6="yes"),$Y6,"")
A7: CASKEY-T3-1-EL | B7: S1 | C7: Caskey 1983 | D7: 304L | F7: 300-series (304 type) | G7: unknown | H7: no | I7: base metal | M7: gaseous in-situ | N7: 69 | Q7: 295 | R7: 21.9 | T7: tensile | U7: elongation | V7: helium | W7: 74 | X7: 48 | Y7: 0.649 | Z7: significant loss | AB7: relative_ratio | AC7: yes | AD7: Caskey DP-1643 Table 3. Condition: annealed. Reference environment 69 MPa helium, not air. Composition from Caskey Table A-1 (nominal). | AE7: =IF(AND($U7="reduction of area",$H7="no"),$Y7,"") | AF7: =IF(AND($U7="reduction of area",$H7="yes"),$Y7,"")
A8: CASKEY-T3-1-RA | B8: S1 | C8: Caskey 1983 | D8: 304L | F8: 300-series (304 type) | G8: unknown | H8: no | I8: base metal | M8: gaseous in-situ | N8: 69 | Q8: 295 | R8: 21.9 | T8: tensile | U8: reduction of area | V8: helium | W8: 81 | X8: 33 | Y8: 0.407 | Z8: significant loss | AB8: relative_ratio | AC8: yes | AD8: Caskey DP-1643 Table 3. Condition: annealed. Reference environment 69 MPa helium, not air. Composition from Caskey Table A-1 (nominal). | AE8: =IF(AND($U8="reduction of area",$H8="no"),$Y8,"") | AF8: =IF(AND($U8="reduction of area",$H8="yes"),$Y8,"")
A9: CASKEY-T3-2-EL | B9: S1 | C9: Caskey 1983 | D9: 304L | F9: 300-series (304 type) | G9: unknown | H9: no | I9: base metal | M9: gaseous in-situ | N9: 69 | Q9: 295 | R9: 21.9 | T9: tensile | U9: elongation | V9: helium | W9: 43 | X9: 41 | Y9: 0.953 | Z9: no measurable loss | AB9: relative_ratio | AC9: yes | AD9: Caskey DP-1643 Table 3. Condition: HERF (high energy rate forged). Reference environment 69 MPa helium, not air. Composition from Caskey Table A-1 (nominal). | AE9: =IF(AND($U9="reduction of area",$H9="no"),$Y9,"") | AF9: =IF(AND($U9="reduction of area",$H9="yes"),$Y9,"")
A10: CASKEY-T3-2-RA | B10: S1 | C10: Caskey 1983 | D10: 304L | F10: 300-series (304 type) | G10: unknown | H10: no | I10: base metal | M10: gaseous in-situ | N10: 69 | Q10: 295 | R10: 21.9 | T10: tensile | U10: reduction of area | V10: helium | W10: 77 | X10: 69 | Y10: 0.896 | Z10: moderate loss | AB10: relative_ratio | AC10: yes | AD10: Caskey DP-1643 Table 3. Condition: HERF (high energy rate forged). Reference environment 69 MPa helium, not air. Composition from Caskey Table A-1 (nominal). | AE10: =IF(AND($U10="reduction of area",$H10="no"),$Y10,"") | AF10: =IF(AND($U10="reduction of area",$H10="yes"),$Y10,"")
A11: CASKEY-T6-1-PS | B11: S1 | C11: Caskey 1983 | D11: 304L | F11: 300-series (304 type) | G11: unknown | H11: no | I11: base metal | M11: gaseous precharge | N11: 69 | Q11: 295 | R11: 21.9 | T11: tensile | U11: plastic strain to failure | V11: uncharged | W11: 1.43 | X11: 0.37 | Y11: 0.259 | Z11: significant loss | AB11: relative_ratio | AC11: no | AD11: Caskey Table 6, smooth specimen; reference = annealed in argon Composition from Caskey Table A-1 (nominal). | AE11: =IF(AND($U11="reduction of area",$H11="no"),$Y11,"") | AF11: =IF(AND($U11="reduction of area",$H11="yes"),$Y11,"")
A12: CASKEY-T6-1-TS | B12: S1 | C12: Caskey 1983 | D12: 304L | F12: 300-series (304 type) | G12: unknown | H12: no | I12: base metal | M12: gaseous precharge | N12: 69 | Q12: 295 | R12: 21.9 | T12: tensile | U12: tensile strength | V12: uncharged | W12: 600 | X12: 530 | Y12: 0.883 | Z12: moderate loss | AB12: relative_ratio | AC12: no | AD12: Caskey Table 6, smooth specimen; hydrogen gas 69 MPa, 200 days at 380 K; reference = annealed 200 d at 380 K in argon Composition from Caskey Table A-1 (nominal). | AE12: =IF(AND($U12="reduction of area",$H12="no"),$Y12,"") | AF12: =IF(AND($U12="reduction of area",$H12="yes"),$Y12,"")
A13: CASKEY-T6-2-PS | B13: S1 | C13: Caskey 1983 | D13: 304L | F13: 300-series (304 type) | G13: unknown | H13: no | I13: base metal | M13: gaseous precharge | N13: 69 | Q13: 295 | R13: 21.9 | T13: tensile | U13: plastic strain to failure | V13: uncharged | W13: 0.24 | X13: 0.13 | Y13: 0.542 | Z13: significant loss | AB13: relative_ratio | AC13: no | AD13: Caskey Table 6, notched specimen; reference = annealed in argon Composition from Caskey Table A-1 (nominal). | AE13: =IF(AND($U13="reduction of area",$H13="no"),$Y13,"") | AF13: =IF(AND($U13="reduction of area",$H13="yes"),$Y13,"")
A14: CASKEY-T6-2-TS | B14: S1 | C14: Caskey 1983 | D14: 304L | F14: 300-series (304 type) | G14: unknown | H14: no | I14: base metal | M14: gaseous precharge | N14: 69 | Q14: 295 | R14: 21.9 | T14: tensile | U14: notched tensile strength | V14: uncharged | W14: 710 | X14: 580 | Y14: 0.817 | Z14: moderate loss | AB14: relative_ratio | AC14: no | AD14: Caskey Table 6, notched specimen; reference = annealed in argon Composition from Caskey Table A-1 (nominal). | AE14: =IF(AND($U14="reduction of area",$H14="no"),$Y14,"") | AF14: =IF(AND($U14="reduction of area",$H14="yes"),$Y14,"")
A15: SAND2012-ch2101-T3111-1 | B15: S2 | C15: San Marchi 2012 | D15: 304L | E15: W69 | F15: 300-series (304 type) | G15: unknown | H15: no | I15: base metal | M15: gaseous in-situ | N15: 69 | Q15: 295 | R15: 21.9 | S15: 0.00067 | T15: tensile | U15: reduction of area | V15: helium | W15: 78 | X15: 71 | Y15: 0.91 | Z15: moderate loss | AB15: relative_ratio | AC15: no | AD15: SAND2012-7321 (San Marchi & Somerday), chapter 2101 Table 3.1.1.1. Annealed; external 69 MPa H2 vs 69 MPa He. Ref [15,23]. | AE15: =IF(AND($U15="reduction of area",$H15="no"),$Y15,"") | AF15: =IF(AND($U15="reduction of area",$H15="yes"),$Y15,"")
A16: SAND2012-ch2101-T3111-2 | B16: S2 | C16: San Marchi 2012 | D16: 304L | F16: 300-series (304 type) | G16: unknown | H16: no | I16: base metal | M16: gaseous in-situ | N16: 34 | P16: 24 | Q16: 295 | R16: 21.9 | T16: tensile | U16: reduction of area | V16: air | W16: 60 | X16: 46 | Y16: 0.767 | Z16: significant loss | AB16: relative_ratio | AC16: no | AD16: SAND2012-7321 (San Marchi & Somerday), chapter 2101 Table 3.1.1.1. Held at test pressure 24 h before loading. Ref [15]. | AE16: =IF(AND($U16="reduction of area",$H16="no"),$Y16,"") | AF16: =IF(AND($U16="reduction of area",$H16="yes"),$Y16,"")
A17: SAND2012-ch2101-T3111-3 | B17: S2 | C17: San Marchi 2012 | D17: 304L | F17: 300-series (304 type) | G17: unknown | H17: no | I17: base metal | M17: gaseous in-situ | N17: 69 | P17: 24 | Q17: 295 | R17: 21.9 | T17: tensile | U17: reduction of area | V17: air | W17: 60 | X17: 44 | Y17: 0.733 | Z17: significant loss | AB17: relative_ratio | AC17: no | AD17: SAND2012-7321 (San Marchi & Somerday), chapter 2101 Table 3.1.1.1. Held at test pressure 24 h before loading. Ref [15]. | AE17: =IF(AND($U17="reduction of area",$H17="no"),$Y17,"") | AF17: =IF(AND($U17="reduction of area",$H17="yes"),$Y17,"")
A18: SAND2012-ch2101-T3111-4 | B18: S2 | C18: San Marchi 2012 | D18: 304L | E18: O76 | F18: 300-series (304 type) | G18: plate | H18: no | I18: base metal | M18: gaseous precharge | N18: 69 | O18: 55 | P18: 240 | Q18: 295 | R18: 21.9 | S18: 0.003 | T18: tensile | U18: reduction of area | V18: air | W18: 77 | X18: 32 | Y18: 0.416 | Z18: significant loss | AB18: relative_ratio | AC18: no | AD18: SAND2012-7321 (San Marchi & Somerday), chapter 2101 Table 3.1.1.1. Annealed plate; precharged 24.1 MPa H2, 473 K, 240 h (55 wppm surface) then tested in 69 MPa H2. Ref [5]. | AE18: =IF(AND($U18="reduction of area",$H18="no"),$Y18,"") | AF18: =IF(AND($U18="reduction of area",$H18="yes"),$Y18,"")
A19: SAND2012-ch2101-T3111-5 | B19: S2 | C19: San Marchi 2012 | D19: 304L | F19: 300-series (304 type) | G19: unknown | H19: no | I19: base metal | M19: gaseous in-situ | N19: 69 | Q19: 295 | R19: 21.9 | T19: tensile | U19: reduction of area | V19: helium | W19: 81 | X19: 33 | Y19: 0.407 | Z19: significant loss | AB19: relative_ratio | AC19: no | AD19: SAND2012-7321 (San Marchi & Somerday), chapter 2101 Table 3.1.1.1. 69 MPa H2 vs 69 MPa He. Ref [4,25]. NOTE: matches Caskey DP-1643 Table 3 annealed 304L; the condition is annealed, not HERF. | AE19: =IF(AND($U19="reduction of area",$H19="no"),$Y19,"") | AF19: =IF(AND($U19="reduction of area",$H19="yes"),$Y19,"")
A20: YOUNES13-EB-110 | B20: S6 | C20: Younes 2013 | D20: 304L EB weld | F20: 300-series (304 type) | G20: weld | H20: yes | I20: weld metal | J20: EBW | M20: gaseous precharge | O20: 110 | Q20: 295 | R20: 21.9 | T20: tensile | U20: reduction of area | V20: uncharged | Y20: 0.61 | Z20: significant loss | AB20: relative_ratio | AC20: no | AD20: Younes et al., Int. J. Hydrogen Energy 38 (2013) 4864. Table 4. 304L tube, thermally charged in hydrogen gas to the stated content; RA loss reported rather than absolute values, so relative_ratio = 1 - loss/100. 304L electron-beam weld, 110 wppm hydrogen, RA loss 39%. | AE20: =IF(AND($U20="reduction of area",$H20="no"),$Y20,"") | AF20: =IF(AND($U20="reduction of area",$H20="yes"),$Y20,"")
A21: YOUNES13-EB-160 | B21: S6 | C21: Younes 2013 | D21: 304L EB weld | F21: 300-series (304 type) | G21: weld | H21: yes | I21: weld metal | J21: EBW | M21: gaseous precharge | O21: 160 | Q21: 295 | R21: 21.9 | T21: tensile | U21: reduction of area | V21: uncharged | Y21: 0.49 | Z21: significant loss | AB21: relative_ratio | AC21: no | AD21: Younes et al., Int. J. Hydrogen Energy 38 (2013) 4864. Table 4. 304L tube, thermally charged in hydrogen gas to the stated content; RA loss reported rather than absolute values, so relative_ratio = 1 - loss/100. 304L electron-beam weld, 160 wppm hydrogen, RA loss 51%. | AE21: =IF(AND($U21="reduction of area",$H21="no"),$Y21,"") | AF21: =IF(AND($U21="reduction of area",$H21="yes"),$Y21,"")
A22: YOUNES13-EB-57 | B22: S6 | C22: Younes 2013 | D22: 304L EB weld | F22: 300-series (304 type) | G22: weld | H22: yes | I22: weld metal | J22: EBW | M22: gaseous precharge | O22: 57 | Q22: 295 | R22: 21.9 | T22: tensile | U22: reduction of area | V22: uncharged | Y22: 0.8 | Z22: moderate loss | AB22: relative_ratio | AC22: no | AD22: Younes et al., Int. J. Hydrogen Energy 38 (2013) 4864. Table 4. 304L tube, thermally charged in hydrogen gas to the stated content; RA loss reported rather than absolute values, so relative_ratio = 1 - loss/100. 304L electron-beam weld, 57 wppm hydrogen, RA loss 20%. | AE22: =IF(AND($U22="reduction of area",$H22="no"),$Y22,"") | AF22: =IF(AND($U22="reduction of area",$H22="yes"),$Y22,"")
A23: YOUNES13-TIG-110 | B23: S6 | C23: Younes 2013 | D23: 304L TIG weld | F23: 300-series (304 type) | G23: weld | H23: yes | I23: weld metal | J23: GTAW | M23: gaseous precharge | O23: 110 | Q23: 295 | R23: 21.9 | T23: tensile | U23: reduction of area | V23: uncharged | Y23: 0.47 | Z23: significant loss | AB23: relative_ratio | AC23: no | AD23: Younes et al., Int. J. Hydrogen Energy 38 (2013) 4864. Table 4. 304L tube, thermally charged in hydrogen gas to the stated content; RA loss reported rather than absolute values, so relative_ratio = 1 - loss/100. 304L TIG weld, 110 wppm hydrogen, RA loss 53%. | AE23: =IF(AND($U23="reduction of area",$H23="no"),$Y23,"") | AF23: =IF(AND($U23="reduction of area",$H23="yes"),$Y23,"")
A24: YOUNES13-TIG-160 | B24: S6 | C24: Younes 2013 | D24: 304L TIG weld | F24: 300-series (304 type) | G24: weld | H24: yes | I24: weld metal | J24: GTAW | M24: gaseous precharge | O24: 160 | Q24: 295 | R24: 21.9 | T24: tensile | U24: reduction of area | V24: uncharged | Y24: 0.35 | Z24: significant loss | AB24: relative_ratio | AC24: no | AD24: Younes et al., Int. J. Hydrogen Energy 38 (2013) 4864. Table 4. 304L tube, thermally charged in hydrogen gas to the stated content; RA loss reported rather than absolute values, so relative_ratio = 1 - loss/100. 304L TIG weld, 160 wppm hydrogen, RA loss 65%. | AE24: =IF(AND($U24="reduction of area",$H24="no"),$Y24,"") | AF24: =IF(AND($U24="reduction of area",$H24="yes"),$Y24,"")
A25: YOUNES13-TIG-57 | B25: S6 | C25: Younes 2013 | D25: 304L TIG weld | F25: 300-series (304 type) | G25: weld | H25: yes | I25: weld metal | J25: GTAW | M25: gaseous precharge | O25: 57 | Q25: 295 | R25: 21.9 | T25: tensile | U25: reduction of area | V25: uncharged | Y25: 0.59 | Z25: significant loss | AB25: relative_ratio | AC25: no | AD25: Younes et al., Int. J. Hydrogen Energy 38 (2013) 4864. Table 4. 304L tube, thermally charged in hydrogen gas to the stated content; RA loss reported rather than absolute values, so relative_ratio = 1 - loss/100. 304L TIG weld, 57 wppm hydrogen, RA loss 41%. | AE25: =IF(AND($U25="reduction of area",$H25="no"),$Y25,"") | AF25: =IF(AND($U25="reduction of area",$H25="yes"),$Y25,"")
A26: YOUNES13-BASE-110 | B26: S6 | C26: Younes 2013 | D26: 304L base metal | F26: 300-series (304 type) | G26: tube | H26: no | I26: base metal | M26: gaseous precharge | O26: 110 | Q26: 295 | R26: 21.9 | T26: tensile | U26: reduction of area | V26: uncharged | Y26: 0.63 | Z26: significant loss | AB26: relative_ratio | AC26: no | AD26: Younes et al., Int. J. Hydrogen Energy 38 (2013) 4864. Table 4. 304L tube, thermally charged in hydrogen gas to the stated content; RA loss reported rather than absolute values, so relative_ratio = 1 - loss/100. 304L base metal, 110 wppm hydrogen, RA loss 37%. | AE26: =IF(AND($U26="reduction of area",$H26="no"),$Y26,"") | AF26: =IF(AND($U26="reduction of area",$H26="yes"),$Y26,"")
A27: YOUNES13-BASE-160 | B27: S6 | C27: Younes 2013 | D27: 304L base metal | F27: 300-series (304 type) | G27: tube | H27: no | I27: base metal | M27: gaseous precharge | O27: 160 | Q27: 295 | R27: 21.9 | T27: tensile | U27: reduction of area | V27: uncharged | Y27: 0.52 | Z27: significant loss | AB27: relative_ratio | AC27: no | AD27: Younes et al., Int. J. Hydrogen Energy 38 (2013) 4864. Table 4. 304L tube, thermally charged in hydrogen gas to the stated content; RA loss reported rather than absolute values, so relative_ratio = 1 - loss/100. 304L base metal, 160 wppm hydrogen, RA loss 48%. | AE27: =IF(AND($U27="reduction of area",$H27="no"),$Y27,"") | AF27: =IF(AND($U27="reduction of area",$H27="yes"),$Y27,"")
A28: YOUNES13-BASE-57 | B28: S6 | C28: Younes 2013 | D28: 304L base metal | F28: 300-series (304 type) | G28: tube | H28: no | I28: base metal | M28: gaseous precharge | O28: 57 | Q28: 295 | R28: 21.9 | T28: tensile | U28: reduction of area | V28: uncharged | Y28: 0.81 | Z28: moderate loss | AB28: relative_ratio | AC28: no | AD28: Younes et al., Int. J. Hydrogen Energy 38 (2013) 4864. Table 4. 304L tube, thermally charged in hydrogen gas to the stated content; RA loss reported rather than absolute values, so relative_ratio = 1 - loss/100. 304L base metal, 57 wppm hydrogen, RA loss 19%. | AE28: =IF(AND($U28="reduction of area",$H28="no"),$Y28,"") | AF28: =IF(AND($U28="reduction of area",$H28="yes"),$Y28,"")
A29: BALCH15-LONG-CENTER-EL | B29: S3 | C29: Balch 2015 | D29: 304L/308L weld | F29: 300-series (304 type) | G29: weld | H29: yes | I29: weld metal | J29: GTAW | K29: ER308L | M29: gaseous precharge | N29: 138 | O29: 139 | P29: 336 | Q29: 295 | R29: 21.9 | S29: 0.00076 | T29: tensile | U29: elongation | V29: uncharged | W29: 44 | X29: 28 | Y29: 0.636 | Z29: significant loss | AA29: 26.49 | AB29: ni_equivalent;relative_ratio | AC29: yes | AD29: Balch et al. PVP2015-45591 Table 3. Multipass GTA weld, gage section 100% weld deposit; longitudinal orientation, center of weld. Precharged 300 C, 138 MPa H2, 2 weeks -> 7700 appm (about 139 wt ppm). Composition is the 308L filler wire; 304L base metal 19.25Cr-10.25Ni. | AE29: =IF(AND($U29="reduction of area",$H29="no"),$Y29,"") | AF29: =IF(AND($U29="reduction of area",$H29="yes"),$Y29,"")
A30: BALCH15-LONG-CENTER-RA | B30: S3 | C30: Balch 2015 | D30: 304L/308L weld | F30: 300-series (304 type) | G30: weld | H30: yes | I30: weld metal | J30: GTAW | K30: ER308L | M30: gaseous precharge | N30: 138 | O30: 139 | P30: 336 | Q30: 295 | R30: 21.9 | S30: 0.00076 | T30: tensile | U30: reduction of area | V30: uncharged | W30: 78 | X30: 34 | Y30: 0.436 | Z30: significant loss | AA30: 26.49 | AB30: ni_equivalent;relative_ratio | AC30: yes | AD30: Balch et al. PVP2015-45591 Table 3. Multipass GTA weld, gage section 100% weld deposit; longitudinal orientation, center of weld. Precharged 300 C, 138 MPa H2, 2 weeks -> 7700 appm (about 139 wt ppm). Composition is the 308L filler wire; 304L base metal 19.25Cr-10.25Ni. | AE30: =IF(AND($U30="reduction of area",$H30="no"),$Y30,"") | AF30: =IF(AND($U30="reduction of area",$H30="yes"),$Y30,"")
A31: BALCH15-LONG-ROOT-EL | B31: S3 | C31: Balch 2015 | D31: 304L/308L weld | F31: 300-series (304 type) | G31: weld | H31: yes | I31: weld metal | J31: GTAW | K31: ER308L | M31: gaseous precharge | N31: 138 | O31: 139 | P31: 336 | Q31: 295 | R31: 21.9 | S31: 0.00076 | T31: tensile | U31: elongation | V31: uncharged | W31: 38 | X31: 21 | Y31: 0.553 | Z31: significant loss | AA31: 26.49 | AB31: ni_equivalent;relative_ratio | AC31: yes | AD31: Balch et al. PVP2015-45591 Table 3. Multipass GTA weld, gage section 100% weld deposit; longitudinal orientation, root of weld. Precharged 300 C, 138 MPa H2, 2 weeks -> 7700 appm (about 139 wt ppm). Composition is the 308L filler wire; 304L base metal 19.25Cr-10.25Ni. | AE31: =IF(AND($U31="reduction of area",$H31="no"),$Y31,"") | AF31: =IF(AND($U31="reduction of area",$H31="yes"),$Y31,"")
A32: BALCH15-LONG-ROOT-RA | B32: S3 | C32: Balch 2015 | D32: 304L/308L weld | F32: 300-series (304 type) | G32: weld | H32: yes | I32: weld metal | J32: GTAW | K32: ER308L | M32: gaseous precharge | N32: 138 | O32: 139 | P32: 336 | Q32: 295 | R32: 21.9 | S32: 0.00076 | T32: tensile | U32: reduction of area | V32: uncharged | W32: 78 | X32: 28 | Y32: 0.359 | Z32: significant loss | AA32: 26.49 | AB32: ni_equivalent;relative_ratio | AC32: yes | AD32: Balch et al. PVP2015-45591 Table 3. Multipass GTA weld, gage section 100% weld deposit; longitudinal orientation, root of weld. Precharged 300 C, 138 MPa H2, 2 weeks -> 7700 appm (about 139 wt ppm). Composition is the 308L filler wire; 304L base metal 19.25Cr-10.25Ni. | AE32: =IF(AND($U32="reduction of area",$H32="no"),$Y32,"") | AF32: =IF(AND($U32="reduction of area",$H32="yes"),$Y32,"")
A33: BALCH15-LONG-TOP-EL | B33: S3 | C33: Balch 2015 | D33: 304L/308L weld | F33: 300-series (304 type) | G33: weld | H33: yes | I33: weld metal | J33: GTAW | K33: ER308L | M33: gaseous precharge | N33: 138 | O33: 139 | P33: 336 | Q33: 295 | R33: 21.9 | S33: 0.00076 | T33: tensile | U33: elongation | V33: uncharged | W33: 56 | X33: 28 | Y33: 0.5 | Z33: significant loss | AA33: 26.49 | AB33: ni_equivalent;relative_ratio | AC33: yes | AD33: Balch et al. PVP2015-45591 Table 3. Multipass GTA weld, gage section 100% weld deposit; longitudinal orientation, top of weld. Precharged 300 C, 138 MPa H2, 2 weeks -> 7700 appm (about 139 wt ppm). Composition is the 308L filler wire; 304L base metal 19.25Cr-10.25Ni. | AE33: =IF(AND($U33="reduction of area",$H33="no"),$Y33,"") | AF33: =IF(AND($U33="reduction of area",$H33="yes"),$Y33,"")
A34: BALCH15-LONG-TOP-RA | B34: S3 | C34: Balch 2015 | D34: 304L/308L weld | F34: 300-series (304 type) | G34: weld | H34: yes | I34: weld metal | J34: GTAW | K34: ER308L | M34: gaseous precharge | N34: 138 | O34: 139 | P34: 336 | Q34: 295 | R34: 21.9 | S34: 0.00076 | T34: tensile | U34: reduction of area | V34: uncharged | W34: 77 | X34: 40 | Y34: 0.519 | Z34: significant loss | AA34: 26.49 | AB34: ni_equivalent;relative_ratio | AC34: yes | AD34: Balch et al. PVP2015-45591 Table 3. Multipass GTA weld, gage section 100% weld deposit; longitudinal orientation, top of weld. Precharged 300 C, 138 MPa H2, 2 weeks -> 7700 appm (about 139 wt ppm). Composition is the 308L filler wire; 304L base metal 19.25Cr-10.25Ni. | AE34: =IF(AND($U34="reduction of area",$H34="no"),$Y34,"") | AF34: =IF(AND($U34="reduction of area",$H34="yes"),$Y34,"")
A35: BALCH15-TRAN-CENTER-EL | B35: S3 | C35: Balch 2015 | D35: 304L/308L weld | F35: 300-series (304 type) | G35: weld | H35: yes | I35: weld metal | J35: GTAW | K35: ER308L | M35: gaseous precharge | N35: 138 | O35: 139 | P35: 336 | Q35: 295 | R35: 21.9 | S35: 0.00076 | T35: tensile | U35: elongation | V35: uncharged | W35: 43 | X35: 24 | Y35: 0.558 | Z35: significant loss | AA35: 26.49 | AB35: ni_equivalent;relative_ratio | AC35: yes | AD35: Balch et al. PVP2015-45591 Table 3. Multipass GTA weld, gage section 100% weld deposit; transverse orientation, center of weld. Precharged 300 C, 138 MPa H2, 2 weeks -> 7700 appm (about 139 wt ppm). Composition is the 308L filler wire; 304L base metal 19.25Cr-10.25Ni. | AE35: =IF(AND($U35="reduction of area",$H35="no"),$Y35,"") | AF35: =IF(AND($U35="reduction of area",$H35="yes"),$Y35,"")
A36: BALCH15-TRAN-CENTER-RA | B36: S3 | C36: Balch 2015 | D36: 304L/308L weld | F36: 300-series (304 type) | G36: weld | H36: yes | I36: weld metal | J36: GTAW | K36: ER308L | M36: gaseous precharge | N36: 138 | O36: 139 | P36: 336 | Q36: 295 | R36: 21.9 | S36: 0.00076 | T36: tensile | U36: reduction of area | V36: uncharged | W36: 80 | X36: 34 | Y36: 0.425 | Z36: significant loss | AA36: 26.49 | AB36: ni_equivalent;relative_ratio | AC36: yes | AD36: Balch et al. PVP2015-45591 Table 3. Multipass GTA weld, gage section 100% weld deposit; transverse orientation, center of weld. Precharged 300 C, 138 MPa H2, 2 weeks -> 7700 appm (about 139 wt ppm). Composition is the 308L filler wire; 304L base metal 19.25Cr-10.25Ni. | AE36: =IF(AND($U36="reduction of area",$H36="no"),$Y36,"") | AF36: =IF(AND($U36="reduction of area",$H36="yes"),$Y36,"")
A37: BALCH15-TRAN-ROOT-EL | B37: S3 | C37: Balch 2015 | D37: 304L/308L weld | F37: 300-series (304 type) | G37: weld | H37: yes | I37: weld metal | J37: GTAW | K37: ER308L | M37: gaseous precharge | N37: 138 | O37: 139 | P37: 336 | Q37: 295 | R37: 21.9 | S37: 0.00076 | T37: tensile | U37: elongation | V37: uncharged | W37: 38 | X37: 24 | Y37: 0.632 | Z37: significant loss | AA37: 26.49 | AB37: ni_equivalent;relative_ratio | AC37: yes | AD37: Balch et al. PVP2015-45591 Table 3. Multipass GTA weld, gage section 100% weld deposit; transverse orientation, root of weld. Precharged 300 C, 138 MPa H2, 2 weeks -> 7700 appm (about 139 wt ppm). Composition is the 308L filler wire; 304L base metal 19.25Cr-10.25Ni. | AE37: =IF(AND($U37="reduction of area",$H37="no"),$Y37,"") | AF37: =IF(AND($U37="reduction of area",$H37="yes"),$Y37,"")
A38: BALCH15-TRAN-ROOT-RA | B38: S3 | C38: Balch 2015 | D38: 304L/308L weld | F38: 300-series (304 type) | G38: weld | H38: yes | I38: weld metal | J38: GTAW | K38: ER308L | M38: gaseous precharge | N38: 138 | O38: 139 | P38: 336 | Q38: 295 | R38: 21.9 | S38: 0.00076 | T38: tensile | U38: reduction of area | V38: uncharged | W38: 83 | X38: 41 | Y38: 0.494 | Z38: significant loss | AA38: 26.49 | AB38: ni_equivalent;relative_ratio | AC38: yes | AD38: Balch et al. PVP2015-45591 Table 3. Multipass GTA weld, gage section 100% weld deposit; transverse orientation, root of weld. Precharged 300 C, 138 MPa H2, 2 weeks -> 7700 appm (about 139 wt ppm). Composition is the 308L filler wire; 304L base metal 19.25Cr-10.25Ni. | AE38: =IF(AND($U38="reduction of area",$H38="no"),$Y38,"") | AF38: =IF(AND($U38="reduction of area",$H38="yes"),$Y38,"")
A39: BALCH15-TRAN-TOP-EL | B39: S3 | C39: Balch 2015 | D39: 304L/308L weld | F39: 300-series (304 type) | G39: weld | H39: yes | I39: weld metal | J39: GTAW | K39: ER308L | M39: gaseous precharge | N39: 138 | O39: 139 | P39: 336 | Q39: 295 | R39: 21.9 | S39: 0.00076 | T39: tensile | U39: elongation | V39: uncharged | W39: 54 | X39: 33 | Y39: 0.611 | Z39: significant loss | AA39: 26.49 | AB39: ni_equivalent;relative_ratio | AC39: yes | AD39: Balch et al. PVP2015-45591 Table 3. Multipass GTA weld, gage section 100% weld deposit; transverse orientation, top of weld. Precharged 300 C, 138 MPa H2, 2 weeks -> 7700 appm (about 139 wt ppm). Composition is the 308L filler wire; 304L base metal 19.25Cr-10.25Ni. | AE39: =IF(AND($U39="reduction of area",$H39="no"),$Y39,"") | AF39: =IF(AND($U39="reduction of area",$H39="yes"),$Y39,"")
A40: BALCH15-TRAN-TOP-RA | B40: S3 | C40: Balch 2015 | D40: 304L/308L weld | F40: 300-series (304 type) | G40: weld | H40: yes | I40: weld metal | J40: GTAW | K40: ER308L | M40: gaseous precharge | N40: 138 | O40: 139 | P40: 336 | Q40: 295 | R40: 21.9 | S40: 0.00076 | T40: tensile | U40: reduction of area | V40: uncharged | W40: 82 | X40: 38 | Y40: 0.463 | Z40: significant loss | AA40: 26.49 | AB40: ni_equivalent;relative_ratio | AC40: yes | AD40: Balch et al. PVP2015-45591 Table 3. Multipass GTA weld, gage section 100% weld deposit; transverse orientation, top of weld. Precharged 300 C, 138 MPa H2, 2 weeks -> 7700 appm (about 139 wt ppm). Composition is the 308L filler wire; 304L base metal 19.25Cr-10.25Ni. | AE40: =IF(AND($U40="reduction of area",$H40="no"),$Y40,"") | AF40: =IF(AND($U40="reduction of area",$H40="yes"),$Y40,"")
...

Sheet Summary
A1: HE-Austenite v1.0 — summary
A2: Gaseous hydrogen only. All figures below are live formulas over the Data sheet.
A4: Counts
A5: Total records | B5: =COUNTA(Data!A2:A114)
A6: Reduction-of-area rows | B6: =COUNT(Data!AE2:AE114)+COUNT(Data!AF2:AF114)
A7: Weld rows | B7: =COUNTIF(Data!H2:H114,"yes")
A8: Base metal rows | B8: =COUNTIF(Data!H2:H114,"no")
A9: Rows independently re-extracted and matched | B9: =COUNTIF(Data!AC2:AC114,"yes")
A11: Median RRA
A12: Base metal | B12: =MEDIAN(Data!AE2:AE114)
A13: Welds | B13: =MEDIAN(Data!AF2:AF114)
A15: By material family
A16: Family | B16: RA rows | C16: Mean RRA | D16: Rows with significant loss (RRA < 0.80)
A17: 300-series (304 type) | B17: =COUNTIFS(Data!$F$2:$F$114,A17,Data!$U$2:$U$114,"reduction of area") | C17: =IFERROR(AVERAGEIFS(Data!$Y$2:$Y$114,Data!$F$2:$F$114,A17,Data!$U$2:$U$114,"reduction of area"),"") | D17: =COUNTIFS(Data!$F$2:$F$114,A17,Data!$U$2:$U$114,"reduction of area",Data!$Z$2:$Z$114,"significant loss")
A18: 300-series (316/317 type) | B18: =COUNTIFS(Data!$F$2:$F$114,A18,Data!$U$2:$U$114,"reduction of area") | C18: =IFERROR(AVERAGEIFS(Data!$Y$2:$Y$114,Data!$F$2:$F$114,A18,Data!$U$2:$U$114,"reduction of area"),"") | D18: =COUNTIFS(Data!$F$2:$F$114,A18,Data!$U$2:$U$114,"reduction of area",Data!$Z$2:$Z$114,"significant loss")
A19: 300-series stabilised (321/347) | B19: =COUNTIFS(Data!$F$2:$F$114,A19,Data!$U$2:$U$114,"reduction of area") | C19: =IFERROR(AVERAGEIFS(Data!$Y$2:$Y$114,Data!$F$2:$F$114,A19,Data!$U$2:$U$114,"reduction of area"),"") | D19: =COUNTIFS(Data!$F$2:$F$114,A19,Data!$U$2:$U$114,"reduction of area",Data!$Z$2:$Z$114,"significant loss")
A20: N-strengthened (21-6-9) | B20: =COUNTIFS(Data!$F$2:$F$114,A20,Data!$U$2:$U$114,"reduction of area") | C20: =IFERROR(AVERAGEIFS(Data!$Y$2:$Y$114,Data!$F$2:$F$114,A20,Data!$U$2:$U$114,"reduction of area"),"") | D20: =COUNTIFS(Data!$F$2:$F$114,A20,Data!$U$2:$U$114,"reduction of area",Data!$Z$2:$Z$114,"significant loss")
A21: N-strengthened (22-13-5) | B21: =COUNTIFS(Data!$F$2:$F$114,A21,Data!$U$2:$U$114,"reduction of area") | C21: =IFERROR(AVERAGEIFS(Data!$Y$2:$Y$114,Data!$F$2:$F$114,A21,Data!$U$2:$U$114,"reduction of area"),"") | D21: =COUNTIFS(Data!$F$2:$F$114,A21,Data!$U$2:$U$114,"reduction of area",Data!$Z$2:$Z$114,"significant loss")
A22: duplex | B22: =COUNTIFS(Data!$F$2:$F$114,A22,Data!$U$2:$U$114,"reduction of area") | C22: =IFERROR(AVERAGEIFS(Data!$Y$2:$Y$114,Data!$F$2:$F$114,A22,Data!$U$2:$U$114,"reduction of area"),"") | D22: =COUNTIFS(Data!$F$2:$F$114,A22,Data!$U$2:$U$114,"reduction of area",Data!$Z$2:$Z$114,"significant loss")
A23: high-Ni austenitic (310) | B23: =COUNTIFS(Data!$F$2:$F$114,A23,Data!$U$2:$U$114,"reduction of area") | C23: =IFERROR(AVERAGEIFS(Data!$Y$2:$Y$114,Data!$F$2:$F$114,A23,Data!$U$2:$U$114,"reduction of area"),"") | D23: =COUNTIFS(Data!$F$2:$F$114,A23,Data!$U$2:$U$114,"reduction of area",Data!$Z$2:$Z$114,"significant loss")
A24: precipitation-strengthened (A286) | B24: =COUNTIFS(Data!$F$2:$F$114,A24,Data!$U$2:$U$114,"reduction of area") | C24: =IFERROR(AVERAGEIFS(Data!$Y$2:$Y$114,Data!$F$2:$F$114,A24,Data!$U$2:$U$114,"reduction of area"),"") | D24: =COUNTIFS(Data!$F$2:$F$114,A24,Data!$U$2:$U$114,"reduction of area",Data!$Z$2:$Z$114,"significant loss")

Sheet Data dictionary
A1: Column | B1: Meaning | C1: Units / values | D1: Records populated
A2: record_id | B2: Unique id: source, table, row | D2: 113 of 113
A3: source_id | B3: Key into the Sources sheet | D3: 113 of 113
A4: source_short | B4: Author and year | D4: 113 of 113
A5: alloy | B5: Alloy designation, standardised | D5: 113 of 113
A6: heat | B6: Heat or cast id where reported | D6: 16 of 113
A7: material_family | B7: Grouping used for analysis | D7: 113 of 113
A8: product_form | B8: plate, bar, sheet, tube, weld | D8: 113 of 113
A9: is_weld | B9: Gauge section contains weld metal | C9: yes / no | D9: 113 of 113
A10: zone | B10: Part of the joint tested | C10: base metal / weld metal / HAZ / whole joint | D10: 113 of 113
A11: weld_process | B11: Welding process | C11: GTAW, GMAW, PAW, EBW, laser | D11: 60 of 113
A12: filler_metal | B12: Filler wire | D12: 50 of 113
A13: ferrite_number | B13: Ferrite number where reported | C13: FN | D13: 2 of 113
A14: hydrogen_exposure | B14: How hydrogen was introduced | C14: gaseous in-situ / gaseous precharge | D14: 113 of 113
A15: h2_pressure_MPa | B15: Hydrogen gas pressure | C15: MPa | D15: 104 of 113
A16: hydrogen_content_wppm | B16: Hydrogen content | C16: wt ppm | D16: 52 of 113
A17: charging_time_h | B17: Precharging duration | C17: hours | D17: 45 of 113
A18: test_temperature_K | B18: Test temperature | C18: K | D18: 113 of 113
A19: test_temperature_C | B19: Test temperature | C19: deg C | D19: 113 of 113
A20: strain_rate_per_s | B20: Nominal strain rate | C20: 1/s | D20: 64 of 113
A21: test_type | B21: Test method | C21: tensile / SSRT | D21: 113 of 113
A22: property_name | B22: Property measured | D22: 113 of 113
A23: reference_environment | B23: What hydrogen is compared against | C23: air / helium / nitrogen / argon / uncharged | D23: 113 of 113
A24: property_reference | B24: Value in the reference environment | C24: % or MPa | D24: 103 of 113
A25: property_h2 | B25: Value in or after hydrogen | C25: % or MPa | D25: 103 of 113
A26: relative_ratio | B26: property_h2 / property_reference, or the ratio as the source printed it where absolute values were not given | C26: 1.0 = no loss | D26: 113 of 113
A27: embrittlement_flag | B27: Banding of relative_ratio | C27: no measurable loss >=0.95 / moderate 0.80-0.95 / significant <0.80 | D27: 113 of 113
A28: ni_equivalent | B28: Nickel equivalent (Hirayama) where composition was reported | C28: wt % | D28: 14 of 113
A29: derived | B29: Fields computed rather than reported | D29: 113 of 113
A30: verified | B30: Independently re-extracted and matched | C30: yes / no | D30: 113 of 113
A31: notes | B31: Source table, conditions, caveats | D31: 113 of 113

Sheet Sources
A1: Source id | B1: Citation | C1: Link | D1: Access
A2: S1 | B2: Caskey GR Jr. Hydrogen Compatibility Handbook for Stainless Steels. DP-1643, Savannah River Laboratory, June 1983. | C2: https://www.osti.gov/biblio/5906050 | D2: open
A3: S2 | B3: San Marchi C, Somerday BP (eds). Technical Reference on Hydrogen Compatibility of Materials. SAND2012-7321, Sandia National Laboratories, 2012. | C3: https://h2tools.org/technical-reference | D3: open
A4: S3 | B4: Balch DK, San Marchi C, et al. Effect of hydrogen on tensile strength and ductility of multipass 304L/308L welds. PVP2015-45591, ASME, 2015. | D4: paywalled
A5: S4 | B5: Michler T, Lee Y, Gangloff RP, Naumann J. Influence of macro segregation on hydrogen environment embrittlement of SUS 316L. Int J Hydrogen Energy 34(7) 2009: 3201-3209. | C5: https://doi.org/10.1016/j.ijhydene.2009.02.015 | D5: paywalled
A6: S5 | B6: Nakamura J, Okazaki S, Matsunaga H, Matsuoka S. SSRT and fatigue life properties of 317L weld metal in high-pressure hydrogen gas. Trans JSME 84(857) 2018 (Japanese). | C6: https://doi.org/10.1299/transjsme.17-00437 | D6: open
A7: S6 | B7: Younes CM, Steele AM, Nicholson JA, Barnett CJ. Influence of hydrogen content on the tensile properties and fracture of austenitic stainless steel welds. Int J Hydrogen Energy 38 2013: 4864-4876. | D7: paywalled
A8: S7 | B8: Iyer KJL. The influence of hydrogen on the mechanical properties and structure of a stable 304 stainless steel. Canadian Metallurgical Quarterly, 1989. | D8: paywalled
A9: S8 | B9: Fukunaga A. Hydrogen embrittlement behaviors during SSRT tests in gaseous hydrogen for cold-worked type 316 and A286 used in hydrogen refueling stations. Eng Failure Analysis 160 (2024) 108158. | C9: https://doi.org/10.1016/j.engfailanal.2024.108158 | D9: paywalled
A10: S9 | B10: Matsuoka S, Yamabe J, Matsunaga H. Hydrogen-induced ductility loss of austenitic stainless steels for SSRT in high-pressure hydrogen gas. Solid State Phenomena 258 (2017) 259-264. | C10: https://doi.org/10.4028/www.scientific.net/SSP.258.259 | D10: paywalled

Sheet Extraction log
A1: Source | B1: Status | C1: Reason
A2: Caskey DP-1643 | B2: extracted | C2: Tables 3, 6, 10, 11; compositions from Table A-1. Remaining data is in figures.
A3: SAND2012-7321 chapters 2101, 2103, 2104, 2201, 2202, 1600 | B3: extracted | C3: Smooth and notched tensile tables plus weld tables.
A4: Balch 2015 | B4: extracted | C4: Table 3, all six weld positions, both orientations.
A5: Nakamura 2018 | B5: extracted | C5: Base metal and 317L weld metal, as-welded and solution-treated.
A6: Michler 2009 | B6: extracted | C6: Table 2, two heats of 316L.
A7: Younes 2013 | B7: extracted | C7: Table 4, RA loss at three hydrogen contents.
A8: Iyer 1989 | B8: extracted | C8: Table 1; charged in Ar-3%H2 gas at 1050 C, so in scope.
A9: Fukunaga 2024 | B9: extracted | C9: 316CW and A286 values given in the text.
A10: Matsuoka 2017 (SSP) | B10: partly extracted | C10: Only the Type 304 room-temperature RRA (0.37) is numeric; the RRA vs Nieq data is figure-only.
A11: Yamabe 2017 | B11: not extracted | C11: RRA appears only in figures. Ten steels with Nieq already computed; the best candidate for digitisation.
A12: Zhang 2013 | B12: not extracted | C12: RRA vs prestrain and Nieq is figure-only.
... A21: Fu 2020, Zhou 2022/2024, Yun 2023, Choi 2024, Xu 2021, Astafurova 2023, Maritsa 2026, Sabzi 2025, Zhou 2023 (PAW 304), Hempel 2022 (CrMnNi PTIG) | B21: excluded | C21: Electrochemical or cathodic charging, outside the gaseous-hydrogen scope.
